Workbook

Sheet Customers
A1: CustomerID | B1: CustomerName | C1: Region | D1: Region_Clean
A2: 1 | B2: Customer 001 | C2: North | D2: =IF(C2="","",PROPER(TRIM(C2))) -> North
A3: 2 | B3: Customer 002 | C3: North | D3: =IF(C3="","",PROPER(TRIM(C3))) -> North
A4: 3 | B4: Customer 003 | C4: East | D4: =IF(C4="","",PROPER(TRIM(C4))) -> East
A5: 4 | B5: Customer 004 | C5: South | D5: =IF(C5="","",PROPER(TRIM(C5))) -> South
A6: 5 | B6: Customer 005 | C6: South | D6: =IF(C6="","",PROPER(TRIM(C6))) -> South
A7: 6 | B7: Customer 006 | C7: South | D7: =IF(C7="","",PROPER(TRIM(C7))) -> South
A8: 7 | B8: Customer 007 | C8: North | D8: =IF(C8="","",PROPER(TRIM(C8))) -> North
A9: 8 | B9: Customer 008 | C9: North | D9: =IF(C9="","",PROPER(TRIM(C9))) -> North
A10: 9 | B10: Customer 009 | C10: West | D10: =IF(C10="","",PROPER(TRIM(C10))) -> West
A11: 10 | B11: Customer 010 | C11: North | D11: =IF(C11="","",PROPER(TRIM(C11))) -> North
A12: 11 | B12: Customer 011 | C12: North | D12: =IF(C12="","",PROPER(TRIM(C12))) -> North
A13: 12 | B13: Customer 012 | C13: north | D13: =IF(C13="","",PROPER(TRIM(C13))) -> North
... A78: 77 | B78: Customer 077 | C78: East | D78: =IF(C78="","",PROPER(TRIM(C78))) -> East
A79: 78 | B79: Customer 078 | D79: =IF(C79="","",PROPER(TRIM(C79)))
A80: 79 | B80: Customer 079 | C80: West | D80: =IF(C80="","",PROPER(TRIM(C80))) -> West
A81: 80 | B81: Customer 080 | C81: West | D81: =IF(C81="","",PROPER(TRIM(C81))) -> West
A82: 81 | B82: Customer 081 | C82: West | D82: =IF(C82="","",PROPER(TRIM(C82))) -> West
A83: 82 | B83: Customer 082 | C83: South | D83: =IF(C83="","",PROPER(TRIM(C83))) -> South
A84: 83 | B84: Customer 083 | C84: East | D84: =IF(C84="","",PROPER(TRIM(C84))) -> East
A85: 84 | B85: Customer 084 | C85: South | D85: =IF(C85="","",PROPER(TRIM(C85))) -> South
A86: 85 | B86: Customer 085 | C86: South | D86: =IF(C86="","",PROPER(TRIM(C86))) -> South
A87: 86 | B87: Customer 086 | C87: East | D87: =IF(C87="","",PROPER(TRIM(C87))) -> East
A88: 87 | B88: Customer 087 | C88: West | D88: =IF(C88="","",PROPER(TRIM(C88))) -> West
A89: 88 | B89: Customer 088 | C89: West | D89: =IF(C89="","",PROPER(TRIM(C89))) -> West
A90: 89 | B90: Customer 089 | C90: East | D90: =IF(C90="","",PROPER(TRIM(C90))) -> East
A91: 90 | B91: Customer 090 | C91: South | D91: =IF(C91="","",PROPER(TRIM(C91))) -> South
... A301: 300 | B301: Customer 300 | C301: North | D301: =IF(C301="","",PROPER(TRIM(C301))) -> North

Sheet Products
A1: ProductID | B1: ProductName | C1: Category | D1: ListPrice
A2: 1 | B2: Laptop | C2: Electronics | D2: 750
A3: 2 | B3: Monitor | C3: Electronics | D3: 220
A4: 3 | B4: Keyboard | C4: Accessories | D4: 45
A5: 4 | B5: Mouse | C5: Accessories | D5: 25
A6: 5 | B6: Desk | C6: Furniture | D6: 180
A7: 6 | B7: Chair | C7: Furniture | D7: 140
A8: 7 | B8: Headphones | C8: Electronics | D8: 65
A9: 8 | B9: Webcam | C9: Accessories | D9: 55
A10: 9 | B10: Lamp | C10: Home | D10: 30
A11: 10 | B11: Notebook | C11: Office | D11: 8
A12: 11 | B12: Backpack | C12: Office | D12: 48
A13: 12 | B13: Storage Box | C13: Home | D13: 22

Sheet MonthlyOrdersAnalysis
A1: Status | B1: (Multiple Items)
A3: Row Labels | B3: Count of OrderID
A4: Jan | B4: 202
A5: Feb | B5: 185
A6: Mar | B6: 183 | E6: June | F6: May
A7: Apr | B7: 171 | E7: =150969/202 -> 747.37129 | F7: =125556/202 -> 621.56436
A8: May | B8: 202
A9: Jun | B9: 202
A10: Grand Total | B10: 1145

Sheet Orders
A1: OrderID | B1: CustomerID | C1: OrderDate | D1: Status
A2: 1001 | B2: 77 | C2: 46042 | D2: Shipped
A3: 1002 | B3: 108 | C3: 46033 | D3: Cancelled
A4: 1003 | B4: 91 | C4: 46083 | D4: Cancelled
A5: 1004 | B5: 128 | C5: 46194 | D5: Cancelled
A6: 1005 | B6: 236 | C6: 46143 | D6: Delivered
A7: 1006 | B7: 261 | C7: 46094 | D7: Delivered
A8: 1007 | B8: 223 | C8: 46032 | D8: Delivered
A9: 1008 | B9: 276 | C9: 46134 | D9: Delivered
A10: 1009 | B10: 154 | C10: 46054 | D10: Delivered
A11: 1010 | B11: 90 | C11: 46196 | D11: Delivered
A12: 1011 | B12: 110 | C12: 46142 | D12: Delivered
A13: 1012 | B13: 24 | C13: 46073 | D13: Delivered
... A1201: 2200 | B1201: 56 | C1201: 46102 | D1201: Shipped

Sheet MonthlySalesAnalysis
A3: Row Labels | B3: Sum of IncludedLineSales
A4: Jan | B4: 134137
A5: Feb | B5: 117346
A6: Mar | B6: 123202 | F6: =(150969-125556)/125556 -> 0.20240371
A7: Apr | B7: 104326
A8: May | B8: 125556
A9: Jun | B9: 150969
A10: Grand Total | B10: 755536

Sheet ProductSalesAnalysis
A3: Sum of IncludedLineSales | B3: Column Labels
A4: Row Labels | B4: 2026-05 | C4: 2026-06 | D4: Grand Total
A5: Backpack | B5: 4224 | C5: 6096 | D5: 10320
A6: Chair | B6: 10360 | C6: 7420 | D6: 17780
A7: Desk | B7: 11160 | C7: 14760 | D7: 25920
A8: Headphones | B8: 5980 | C8: 5395 | D8: 11375
A9: Keyboard | B9: 2925 | C9: 3285 | D9: 6210
A10: Lamp | B10: 2580 | C10: 2430 | D10: 5010
A11: Laptop | B11: 57750 | C11: 77250 | D11: 135000
A12: Monitor | B12: 20240 | C12: 24860 | D12: 45100
A13: Mouse | B13: 2150 | C13: 1400 | D13: 3550
A14: Notebook | B14: 608 | C14: 736 | D14: 1344
A15: Storage Box | B15: 1804 | C15: 2002 | D15: 3806
A16: Webcam | B16: 5775 | C16: 5335 | D16: 11110
A17: Grand Total | B17: 125556 | C17: 150969 | D17: 276525

Sheet OrderItems
A1: OrderItemID | B1: OrderID | C1: ProductID | D1: Quantity | E1: UnitPrice | F1: LineSales | G1: OrderStatus | H1: IncludedLineSales | I1: OrderDate | J1: Gross Order Sales | K1: =SUM(H2:H2428) -> 755536 | L1: ProductName | M1: OrderMonth
A2: 1 | B2: 1001 | C2: 1 | D2: 2 | E2: 750 | F2: =D2*E2 -> 1500 | G2: =VLOOKUP(B2,Orders!$A$2:$D$1201,4,FALSE) -> Shipped | H2: =IF(G2="Cancelled",0,F2) -> 1500 | I2: =VLOOKUP(B2,Orders!$A$2:$D$1201,3,FALSE) -> 46042 | J2: Total non-cancelled orders | K2: =COUNTIF(Orders!$D$2:$D$1201,"Delivered")+COUNTIF(Orders!$D$2:$D$1201,"Shipped")+COUNTIF(Orders!$D$2:$D$1201,"Pending") -> 1145 | L2: =VLOOKUP(C2,Products!$A$2:$D$13,2,FALSE) -> Laptop | M2: =TEXT(I2,"yyyy-mm") -> 2026-01
A3: 2 | B3: 1001 | C3: 6 | D3: 4 | E3: 140 | F3: =D3*E3 -> 560 | G3: =VLOOKUP(B3,Orders!$A$2:$D$1201,4,FALSE) -> Shipped | H3: =IF(G3="Cancelled",0,F3) -> 560 | I3: =VLOOKUP(B3,Orders!$A$2:$D$1201,3,FALSE) -> 46042 | J3: Average Order Value | K3: =K1/K2 -> 659.85677 | L3: =VLOOKUP(C3,Products!$A$2:$D$13,2,FALSE) -> Chair | M3: =TEXT(I3,"yyyy-mm") -> 2026-01
A4: 3 | B4: 1001 | C4: 10 | D4: 2 | E4: 8 | F4: =D4*E4 -> 16 | G4: =VLOOKUP(B4,Orders!$A$2:$D$1201,4,FALSE) -> Shipped | H4: =IF(G4="Cancelled",0,F4) -> 16 | I4: =VLOOKUP(B4,Orders!$A$2:$D$1201,3,FALSE) -> 46042 | L4: =VLOOKUP(C4,Products!$A$2:$D$13,2,FALSE) -> Notebook | M4: =TEXT(I4,"yyyy-mm") -> 2026-01
A5: 4 | B5: 1002 | C5: 4 | D5: 3 | E5: 25 | F5: =D5*E5 -> 75 | G5: =VLOOKUP(B5,Orders!$A$2:$D$1201,4,FALSE) -> Cancelled | H5: =IF(G5="Cancelled",0,F5) -> 0 | I5: =VLOOKUP(B5,Orders!$A$2:$D$1201,3,FALSE) -> 46033 | L5: =VLOOKUP(C5,Products!$A$2:$D$13,2,FALSE) -> Mouse | M5: =TEXT(I5,"yyyy-mm") -> 2026-01
A6: 5 | B6: 1002 | C6: 11 | D6: 4 | E6: 48 | F6: =D6*E6 -> 192 | G6: =VLOOKUP(B6,Orders!$A$2:$D$1201,4,FALSE) -> Cancelled | H6: =IF(G6="Cancelled",0,F6) -> 0 | I6: =VLOOKUP(B6,Orders!$A$2:$D$1201,3,FALSE) -> 46033 | L6: =VLOOKUP(C6,Products!$A$2:$D$13,2,FALSE) -> Backpack | M6: =TEXT(I6,"yyyy-mm") -> 2026-01
A7: 6 | B7: 1002 | C7: 2 | D7: 2 | E7: 220 | F7: =D7*E7 -> 440 | G7: =VLOOKUP(B7,Orders!$A$2:$D$1201,4,FALSE) -> Cancelled | H7: =IF(G7="Cancelled",0,F7) -> 0 | I7: =VLOOKUP(B7,Orders!$A$2:$D$1201,3,FALSE) -> 46033 | L7: =VLOOKUP(C7,Products!$A$2:$D$13,2,FALSE) -> Monitor | M7: =TEXT(I7,"yyyy-mm") -> 2026-01
A8: 7 | B8: 1003 | C8: 1 | D8: 3 | E8: 750 | F8: =D8*E8 -> 2250 | G8: =VLOOKUP(B8,Orders!$A$2:$D$1201,4,FALSE) -> Cancelled | H8: =IF(G8="Cancelled",0,F8) -> 0 | I8: =VLOOKUP(B8,Orders!$A$2:$D$1201,3,FALSE) -> 46083 | L8: =VLOOKUP(C8,Products!$A$2:$D$13,2,FALSE) -> Laptop | M8: =TEXT(I8,"yyyy-mm") -> 2026-03
A9: 8 | B9: 1003 | C9: 3 | D9: 4 | E9: 45 | F9: =D9*E9 -> 180 | G9: =VLOOKUP(B9,Orders!$A$2:$D$1201,4,FALSE) -> Cancelled | H9: =IF(G9="Cancelled",0,F9) -> 0 | I9: =VLOOKUP(B9,Orders!$A$2:$D$1201,3,FALSE) -> 46083 | L9: =VLOOKUP(C9,Products!$A$2:$D$13,2,FALSE) -> Keyboard | M9: =TEXT(I9,"yyyy-mm") -> 2026-03
A10: 9 | B10: 1004 | C10: 3 | D10: 4 | E10: 45 | F10: =D10*E10 -> 180 | G10: =VLOOKUP(B10,Orders!$A$2:$D$1201,4,FALSE) -> Cancelled | H10: =IF(G10="Cancelled",0,F10) -> 0 | I10: =VLOOKUP(B10,Orders!$A$2:$D$1201,3,FALSE) -> 46194 | L10: =VLOOKUP(C10,Products!$A$2:$D$13,2,FALSE) -> Keyboard | M10: =TEXT(I10,"yyyy-mm") -> 2026-06
A11: 10 | B11: 1004 | C11: 2 | D11: 1 | E11: 220 | F11: =D11*E11 -> 220 | G11: =VLOOKUP(B11,Orders!$A$2:$D$1201,4,FALSE) -> Cancelled | H11: =IF(G11="Cancelled",0,F11) -> 0 | I11: =VLOOKUP(B11,Orders!$A$2:$D$1201,3,FALSE) -> 46194 | L11: =VLOOKUP(C11,Products!$A$2:$D$13,2,FALSE) -> Monitor | M11: =TEXT(I11,"yyyy-mm") -> 2026-06
A12: 11 | B12: 1005 | C12: 5 | D12: 2 | E12: 180 | F12: =D12*E12 -> 360 | G12: =VLOOKUP(B12,Orders!$A$2:$D$1201,4,FALSE) -> Delivered | H12: =IF(G12="Cancelled",0,F12) -> 360 | I12: =VLOOKUP(B12,Orders!$A$2:$D$1201,3,FALSE) -> 46143 | L12: =VLOOKUP(C12,Products!$A$2:$D$13,2,FALSE) -> Desk | M12: =TEXT(I12,"yyyy-mm") -> 2026-05
A13: 12 | B13: 1005 | C13: 4 | D13: 1 | E13: 25 | F13: =D13*E13 -> 25 | G13: =VLOOKUP(B13,Orders!$A$2:$D$1201,4,FALSE) -> Delivered | H13: =IF(G13="Cancelled",0,F13) -> 25 | I13: =VLOOKUP(B13,Orders!$A$2:$D$1201,3,FALSE) -> 46143 | L13: =VLOOKUP(C13,Products!$A$2:$D$13,2,FALSE) -> Mouse | M13: =TEXT(I13,"yyyy-mm") -> 2026-05
A14: 13 | B14: 1006 | C14: 11 | D14: 3 | E14: 48 | F14: =D14*E14 -> 144 | G14: =VLOOKUP(B14,Orders!$A$2:$D$1201,4,FALSE) -> Delivered | H14: =IF(G14="Cancelled",0,F14) -> 144 | I14: =VLOOKUP(B14,Orders!$A$2:$D$1201,3,FALSE) -> 46094 | L14: =VLOOKUP(C14,Products!$A$2:$D$13,2,FALSE) -> Backpack | M14: =TEXT(I14,"yyyy-mm") -> 2026-03
A15: 14 | B15: 1006 | C15: 9 | D15: 1 | E15: 30 | F15: =D15*E15 -> 30 | G15: =VLOOKUP(B15,Orders!$A$2:$D$1201,4,FALSE) -> Delivered | H15: =IF(G15="Cancelled",0,F15) -> 30 | I15: =VLOOKUP(B15,Orders!$A$2:$D$1201,3,FALSE) -> 46094 | L15: =VLOOKUP(C15,Products!$A$2:$D$13,2,FALSE) -> Lamp | M15: =TEXT(I15,"yyyy-mm") -> 2026-03
... A2428: 2427 | B2428: 2200 | C2428: 3 | D2428: 1 | E2428: 45 | F2428: =D2428*E2428 -> 45 | G2428: =VLOOKUP(B2428,Orders!$A$2:$D$1201,4,FALSE) -> Shipped | H2428: =IF(G2428="Cancelled",0,F2428) -> 45 | I2428: =VLOOKUP(B2428,Orders!$A$2:$D$1201,3,FALSE) -> 46102 | L2428: =VLOOKUP(C2428,Products!$A$2:$D$13,2,FALSE) -> Keyboard | M2428: =TEXT(I2428,"yyyy-mm") -> 2026-03

Sheet DataQualityLog
A1: Table | B1: Issue | C1: Action | D1: Rows Removed
A2: OrderItems | B2: Exact duplicate of OrderItemID 16 | C2: Removed one copy after checking all columns matched | D2: 1
A3: Customers | B3: Missing Region for CustomerID 78 | C3: Retained customer; left Region blank | D3: 0
A4: Customers | B4: Inconsistent Region capitalization and extra spaces | C4: Created Region_Clean using TRIM and PROPER; preserved blanks | D4: 0
A5: Deliveries | B5: Extra spaces in Carrier for OrderID 1024 | C5: Created Carrier_Clean using TRIM | D5: 0
A6: Deliveries | B6: OrderID 1005 marked Delivered with missing ActualDeliveryDate | C6: Retained; timing unknown; exclude from on-time KPI pending verification | D6: 0

Sheet CarrierAnalysis
A3: Count of OrderID | B3: Column Labels
A4: Row Labels | B4: Late | C4: Not delivered | D4: On time | E4: Unknown | F4: Grand Total | G4: On-time rate
A5: MetroLogistics | B5: 112 | C5: 30 | D5: 243 | F5: 385 | G5: =D5/(D5+B5) -> 0.68450704
A6: ParcelOne | B6: 101 | C6: 30 | D6: 238 | E6: 1 | F6: 370 | G6: =D6/(D6+B6) -> 0.7020649
A7: SwiftShip | B7: 108 | C7: 41 | D7: 241 | F7: 390 | G7: =D7/(D7+B7) -> 0.69054441
A8: Grand Total | B8: 321 | C8: 101 | D8: 722 | E8: 1 | F8: 1145

Sheet OnTimeDispatchAnalysis
A1: DispatchTiming | B1: On time
A3: Row Labels | B3: Column Labels
A4: Row Labels | B4: Late | C4: Not delivered | D4: On time | E4: Unknown | F4: Grand Total | G4: On-time Delivery Rate
A5: MetroLogistics | B5: 81 | C5: 17 | D5: 200 | F5: 298 | G5: =D5/(D5+B5) -> 0.71174377
A6: ParcelOne | B6: 76 | C6: 18 | D6: 188 | E6: 1 | F6: 283 | G6: =D6/(D6+B6) -> 0.71212121
A7: SwiftShip | B7: 84 | C7: 23 | D7: 196 | F7: 303 | G7: =D7/(D7+B7) -> 0.7
A8: Grand Total | B8: 241 | C8: 58 | D8: 584 | E8: 1 | F8: 884

Sheet Deliveries
A1: OrderID | B1: Carrier | C1: PromisedDispatchDate | D1: OrderDispatchDate | E1: PromisedDeliveryDate | F1: ActualDeliveryDate | G1: DeliveryStatusUpdateDate | H1: Carrier_Space_Check | I1: Carrier_Clean | J1: OrderStatus | K1: DeliveryTiming | L1: DispatchTiming | M1: DeliveryTiming | N1: OrderCount | O1: StatusUpdateLagDays
A2: 1001 | B2: SwiftShip | C2: 46044 | D2: 46044 | E2: 46049 | H2: =LEN(B2)-LEN(TRIM(B2)) -> 0 | I2: =TRIM(B2) -> SwiftShip | J2: =VLOOKUP(A2,Orders!$A$2:$D$1201,4,FALSE) -> Shipped | K2: =IF(J2<>"Delivered","Not delivered",IF(OR(E2="",F2=""),"Unknown",IF(F2<=E2,"On time","Late"))) -> Not delivered | L2: =IF(D2="","Not dispatched",IF(C2="","Unknown",IF(D2<=C2,"On time","Late"))) -> On time | M2: On time | N2: =COUNTIF($K$2:$K$1146,M2) -> 722 | O2: =IF(OR(F2="",G2=""),"",G2-F2)
A3: 1005 | B3: ParcelOne | C3: 46145 | D3: 46145 | E3: 46150 | G3: 46150 | H3: =LEN(B3)-LEN(TRIM(B3)) -> 0 | I3: =TRIM(B3) -> ParcelOne | J3: =VLOOKUP(A3,Orders!$A$2:$D$1201,4,FALSE) -> Delivered | K3: =IF(J3<>"Delivered","Not delivered",IF(OR(E3="",F3=""),"Unknown",IF(F3<=E3,"On time","Late"))) -> Unknown | L3: =IF(D3="","Not dispatched",IF(C3="","Unknown",IF(D3<=C3,"On time","Late"))) -> On time | M3: Late | N3: =COUNTIF($K$2:$K$1146,M3) -> 321 | O3: =IF(OR(F3="",G3=""),"",G3-F3)
A4: 1006 | B4: SwiftShip | C4: 46096 | D4: 46096 | E4: 46101 | F4: 46105 | G4: 46105 | H4: =LEN(B4)-LEN(TRIM(B4)) -> 0 | I4: =TRIM(B4) -> SwiftShip | J4: =VLOOKUP(A4,Orders!$A$2:$D$1201,4,FALSE) -> Delivered | K4: =IF(J4<>"Delivered","Not delivered",IF(OR(E4="",F4=""),"Unknown",IF(F4<=E4,"On time","Late"))) -> Late | L4: =IF(D4="","Not dispatched",IF(C4="","Unknown",IF(D4<=C4,"On time","Late"))) -> On time | M4: Unknown | N4: =COUNTIF($K$2:$K$1146,M4) -> 1 | O4: =IF(OR(F4="",G4=""),"",G4-F4) -> 0
A5: 1007 | B5: MetroLogistics | C5: 46034 | D5: 46034 | E5: 46039 | F5: 46039 | G5: 46039 | H5: =LEN(B5)-LEN(TRIM(B5)) -> 0 | I5: =TRIM(B5) -> MetroLogistics | J5: =VLOOKUP(A5,Orders!$A$2:$D$1201,4,FALSE) -> Delivered | K5: =IF(J5<>"Delivered","Not delivered",IF(OR(E5="",F5=""),"Unknown",IF(F5<=E5,"On time","Late"))) -> On time | L5: =IF(D5="","Not dispatched",IF(C5="","Unknown",IF(D5<=C5,"On time","Late"))) -> On time | M5: Not Delivered | N5: =COUNTIF($K$2:$K$1146,M5) -> 101 | O5: =IF(OR(F5="",G5=""),"",G5-F5) -> 0
A6: 1008 | B6: MetroLogistics | C6: 46136 | D6: 46138 | E6: 46141 | F6: 46145 | G6: 46145 | H6: =LEN(B6)-LEN(TRIM(B6)) -> 0 | I6: =TRIM(B6) -> MetroLogistics | J6: =VLOOKUP(A6,Orders!$A$2:$D$1201,4,FALSE) -> Delivered | K6: =IF(J6<>"Delivered","Not delivered",IF(OR(E6="",F6=""),"Unknown",IF(F6<=E6,"On time","Late"))) -> Late | L6: =IF(D6="","Not dispatched",IF(C6="","Unknown",IF(D6<=C6,"On time","Late"))) -> Late | O6: =IF(OR(F6="",G6=""),"",G6-F6) -> 0
A7: 1009 | B7: SwiftShip | C7: 46056 | D7: 46056 | E7: 46061 | F7: 46060 | G7: 46060 | H7: =LEN(B7)-LEN(TRIM(B7)) -> 0 | I7: =TRIM(B7) -> SwiftShip | J7: =VLOOKUP(A7,Orders!$A$2:$D$1201,4,FALSE) -> Delivered | K7: =IF(J7<>"Delivered","Not delivered",IF(OR(E7="",F7=""),"Unknown",IF(F7<=E7,"On time","Late"))) -> On time | L7: =IF(D7="","Not dispatched",IF(C7="","Unknown",IF(D7<=C7,"On time","Late"))) -> On time | M7: On-time delivery rate | N7: =N2/(N2+N3) -> 0.69223394 | O7: =IF(OR(F7="",G7=""),"",G7-F7) -> 0
A8: 1010 | B8: SwiftShip | C8: 46198 | D8: 46198 | E8: 46203 | F8: 46204 | G8: 46204 | H8: =LEN(B8)-LEN(TRIM(B8)) -> 0 | I8: =TRIM(B8) -> SwiftShip | J8: =VLOOKUP(A8,Orders!$A$2:$D$1201,4,FALSE) -> Delivered | K8: =IF(J8<>"Delivered","Not delivered",IF(OR(E8="",F8=""),"Unknown",IF(F8<=E8,"On time","Late"))) -> Late | L8: =IF(D8="","Not dispatched",IF(C8="","Unknown",IF(D8<=C8,"On time","Late"))) -> On time | M8: On-time delivery target | N8: 0.95 | O8: =IF(OR(F8="",G8=""),"",G8-F8) -> 0
A9: 1011 | B9: ParcelOne | C9: 46144 | D9: 46145 | E9: 46149 | F9: 46150 | G9: 46150 | H9: =LEN(B9)-LEN(TRIM(B9)) -> 0 | I9: =TRIM(B9) -> ParcelOne | J9: =VLOOKUP(A9,Orders!$A$2:$D$1201,4,FALSE) -> Delivered | K9: =IF(J9<>"Delivered","Not delivered",IF(OR(E9="",F9=""),"Unknown",IF(F9<=E9,"On time","Late"))) -> Late | L9: =IF(D9="","Not dispatched",IF(C9="","Unknown",IF(D9<=C9,"On time","Late"))) -> Late | M9: Gap below target (percentage points) | N9: =(N8-N7)*100 -> 25.776606 | O9: =IF(OR(F9="",G9=""),"",G9-F9) -> 0
A10: 1012 | B10: MetroLogistics | C10: 46075 | D10: 46075 | E10: 46080 | F10: 46082 | G10: 46082 | H10: =LEN(B10)-LEN(TRIM(B10)) -> 0 | I10: =TRIM(B10) -> MetroLogistics | J10: =VLOOKUP(A10,Orders!$A$2:$D$1201,4,FALSE) -> Delivered | K10: =IF(J10<>"Delivered","Not delivered",IF(OR(E10="",F10=""),"Unknown",IF(F10<=E10,"On time","Late"))) -> Late | L10: =IF(D10="","Not dispatched",IF(C10="","Unknown",IF(D10<=C10,"On time","Late"))) -> On time | O10: =IF(OR(F10="",G10=""),"",G10-F10) -> 0
A11: 1013 | B11: SwiftShip | C11: 46203 | D11: 46204 | E11: 46208 | F11: 46210 | G11: 46211 | H11: =LEN(B11)-LEN(TRIM(B11)) -> 0 | I11: =TRIM(B11) -> SwiftShip | J11: =VLOOKUP(A11,Orders!$A$2:$D$1201,4,FALSE) -> Delivered | K11: =IF(J11<>"Delivered","Not delivered",IF(OR(E11="",F11=""),"Unknown",IF(F11<=E11,"On time","Late"))) -> Late | L11: =IF(D11="","Not dispatched",IF(C11="","Unknown",IF(D11<=C11,"On time","Late"))) -> Late | M11: Updates after delivery date | N11: =COUNTIF($O$2:$O$1146,">0") -> 217 | O11: =IF(OR(F11="",G11=""),"",G11-F11) -> 1
A12: 1014 | B12: MetroLogistics | C12: 46081 | D12: 46081 | E12: 46086 | F12: 46087 | G12: 46087 | H12: =LEN(B12)-LEN(TRIM(B12)) -> 0 | I12: =TRIM(B12) -> MetroLogistics | J12: =VLOOKUP(A12,Orders!$A$2:$D$1201,4,FALSE) -> Delivered | K12: =IF(J12<>"Delivered","Not delivered",IF(OR(E12="",F12=""),"Unknown",IF(F12<=E12,"On time","Late"))) -> Late | L12: =IF(D12="","Not dispatched",IF(C12="","Unknown",IF(D12<=C12,"On time","Late"))) -> On time | M12: Updates after delivery date (%) | N12: =N11/COUNT($O$2:$O$1146) -> 0.20805369 | O12: =IF(OR(F12="",G12=""),"",G12-F12) -> 0
A13: 1015 | B13: SwiftShip | C13: 46177 | D13: 46177 | E13: 46182 | F13: 46183 | G13: 46184 | H13: =LEN(B13)-LEN(TRIM(B13)) -> 0 | I13: =TRIM(B13) -> SwiftShip | J13: =VLOOKUP(A13,Orders!$A$2:$D$1201,4,FALSE) -> Delivered | K13: =IF(J13<>"Delivered","Not delivered",IF(OR(E13="",F13=""),"Unknown",IF(F13<=E13,"On time","Late"))) -> Late | L13: =IF(D13="","Not dispatched",IF(C13="","Unknown",IF(D13<=C13,"On time","Late"))) -> On time | O13: =IF(OR(F13="",G13=""),"",G13-F13) -> 1
A14: 1016 | B14: ParcelOne | C14: 46158 | D14: 46158 | E14: 46163 | F14: 46163 | G14: 46163 | H14: =LEN(B14)-LEN(TRIM(B14)) -> 0 | I14: =TRIM(B14) -> ParcelOne | J14: =VLOOKUP(A14,Orders!$A$2:$D$1201,4,FALSE) -> Delivered | K14: =IF(J14<>"Delivered","Not delivered",IF(OR(E14="",F14=""),"Unknown",IF(F14<=E14,"On time","Late"))) -> On time | L14: =IF(D14="","Not dispatched",IF(C14="","Unknown",IF(D14<=C14,"On time","Late"))) -> On time | M14: Status update finding | O14: =IF(OR(F14="",G14=""),"",G14-F14) -> 0
A15: 1017 | B15: MetroLogistics | C15: 46063 | D15: 46063 | E15: 46068 | F15: 46067 | G15: 46067 | H15: =LEN(B15)-LEN(TRIM(B15)) -> 0 | I15: =TRIM(B15) -> MetroLogistics | J15: =VLOOKUP(A15,Orders!$A$2:$D$1201,4,FALSE) -> Delivered | K15: =IF(J15<>"Delivered","Not delivered",IF(OR(E15="",F15=""),"Unknown",IF(F15<=E15,"On time","Late"))) -> On time | L15: =IF(D15="","Not dispatched",IF(C15="","Unknown",IF(D15<=C15,"On time","Late"))) -> On time | M15: In this synthetic dataset, 20.81% of orders with both dates available had their delivery status updated at least one day after physical delivery. This indicates a reporting delay; it does not explain the physical delivery delays measured by our on-time KPI. | O15: =IF(OR(F15="",G15=""),"",G15-F15) -> 0
A16: 1018 | B16: SwiftShip | C16: 46203 | D16: 46203 | E16: 46208 | F16: 46210 | G16: 46212 | H16: =LEN(B16)-LEN(TRIM(B16)) -> 0 | I16: =TRIM(B16) -> SwiftShip | J16: =VLOOKUP(A16,Orders!$A$2:$D$1201,4,FALSE) -> Delivered | K16: =IF(J16<>"Delivered","Not delivered",IF(OR(E16="",F16=""),"Unknown",IF(F16<=E16,"On time","Late"))) -> Late | L16: =IF(D16="","Not dispatched",IF(C16="","Unknown",IF(D16<=C16,"On time","Late"))) -> On time | O16: =IF(OR(F16="",G16=""),"",G16-F16) -> 2
A17: 1019 | B17: SwiftShip | C17: 46162 | D17: 46162 | E17: 46167 | F17: 46167 | G17: 46167 | H17: =LEN(B17)-LEN(TRIM(B17)) -> 0 | I17: =TRIM(B17) -> SwiftShip | J17: =VLOOKUP(A17,Orders!$A$2:$D$1201,4,FALSE) -> Delivered | K17: =IF(J17<>"Delivered","Not delivered",IF(OR(E17="",F17=""),"Unknown",IF(F17<=E17,"On time","Late"))) -> On time | L17: =IF(D17="","Not dispatched",IF(C17="","Unknown",IF(D17<=C17,"On time","Late"))) -> On time | O17: =IF(OR(F17="",G17=""),"",G17-F17) -> 0
A18: 1020 | B18: SwiftShip | C18: 46067 | D18: 46067 | E18: 46072 | F18: 46072 | G18: 46072 | H18: =LEN(B18)-LEN(TRIM(B18)) -> 0 | I18: =TRIM(B18) -> SwiftShip | J18: =VLOOKUP(A18,Orders!$A$2:$D$1201,4,FALSE) -> Delivered | K18: =IF(J18<>"Delivered","Not delivered",IF(OR(E18="",F18=""),"Unknown",IF(F18<=E18,"On time","Late"))) -> On time | L18: =IF(D18="","Not dispatched",IF(C18="","Unknown",IF(D18<=C18,"On time","Late"))) -> On time | O18: =IF(OR(F18="",G18=""),"",G18-F18) -> 0
A19: 1021 | B19: ParcelOne | C19: 46108 | D19: 46109 | E19: 46113 | F19: 46113 | G19: 46113 | H19: =LEN(B19)-LEN(TRIM(B19)) -> 0 | I19: =TRIM(B19) -> ParcelOne | J19: =VLOOKUP(A19,Orders!$A$2:$D$1201,4,FALSE) -> Delivered | K19: =IF(J19<>"Delivered","Not delivered",IF(OR(E19="",F19=""),"Unknown",IF(F19<=E19,"On time","Late"))) -> On time | L19: =IF(D19="","Not dispatched",IF(C19="","Unknown",IF(D19<=C19,"On time","Late"))) -> Late | O19: =IF(OR(F19="",G19=""),"",G19-F19) -> 0
A20: 1022 | B20: ParcelOne | C20: 46114 | D20: 46114 | E20: 46119 | F20: 46119 | G20: 46119 | H20: =LEN(B20)-LEN(TRIM(B20)) -> 0 | I20: =TRIM(B20) -> ParcelOne | J20: =VLOOKUP(A20,Orders!$A$2:$D$1201,4,FALSE) -> Delivered | K20: =IF(J20<>"Delivered","Not delivered",IF(OR(E20="",F20=""),"Unknown",IF(F20<=E20,"On time","Late"))) -> On time | L20: =IF(D20="","Not dispatched",IF(C20="","Unknown",IF(D20<=C20,"On time","Late"))) -> On time | O20: =IF(OR(F20="",G20=""),"",G20-F20) -> 0
A21: 1023 | B21: MetroLogistics | C21: 46144 | D21: 46144 | E21: 46149 | F21: 46148 | G21: 46148 | H21: =LEN(B21)-LEN(TRIM(B21)) -> 0 | I21: =TRIM(B21) -> MetroLogistics | J21: =VLOOKUP(A21,Orders!$A$2:$D$1201,4,FALSE) -> Delivered | K21: =IF(J21<>"Delivered","Not delivered",IF(OR(E21="",F21=""),"Unknown",IF(F21<=E21,"On time","Late"))) -> On time | L21: =IF(D21="","Not dispatched",IF(C21="","Unknown",IF(D21<=C21,"On time","Late"))) -> On time | O21: =IF(OR(F21="",G21=""),"",G21-F21) -> 0
A22: 1024 | B22: SwiftShip | C22: 46031 | D22: 46031 | E22: 46036 | H22: =LEN(B22)-LEN(TRIM(B22)) -> 2 | I22: =TRIM(B22) -> SwiftShip | J22: =VLOOKUP(A22,Orders!$A$2:$D$1201,4,FALSE) -> Shipped | K22: =IF(J22<>"Delivered","Not delivered",IF(OR(E22="",F22=""),"Unknown",IF(F22<=E22,"On time","Late"))) -> Not delivered | L22: =IF(D22="","Not dispatched",IF(C22="","Unknown",IF(D22<=C22,"On time","Late"))) -> On time | O22: =IF(OR(F22="",G22=""),"",G22-F22)
A23: 1025 | B23: SwiftShip | C23: 46200 | D23: 46200 | E23: 46205 | F23: 46205 | G23: 46206 | H23: =LEN(B23)-LEN(TRIM(B23)) -> 0 | I23: =TRIM(B23) -> SwiftShip | J23: =VLOOKUP(A23,Orders!$A$2:$D$1201,4,FALSE) -> Delivered | K23: =IF(J23<>"Delivered","Not delivered",IF(OR(E23="",F23=""),"Unknown",IF(F23<=E23,"On time","Late"))) -> On time | L23: =IF(D23="","Not dispatched",IF(C23="","Unknown",IF(D23<=C23,"On time","Late"))) -> On time | O23: =IF(OR(F23="",G23=""),"",G23-F23) -> 1
A24: 1026 | B24: SwiftShip | C24: 46052 | D24: 46052 | E24: 46057 | F24: 46058 | G24: 46058 | H24: =LEN(B24)-LEN(TRIM(B24)) -> 0 | I24: =TRIM(B24) -> SwiftShip | J24: =VLOOKUP(A24,Orders!$A$2:$D$1201,4,FALSE) -> Delivered | K24: =IF(J24<>"Delivered","Not delivered",IF(OR(E24="",F24=""),"Unknown",IF(F24<=E24,"On time","Late"))) -> Late | L24: =IF(D24="","Not dispatched",IF(C24="","Unknown",IF(D24<=C24,"On time","Late"))) -> On time | O24: =IF(OR(F24="",G24=""),"",G24-F24) -> 0
A25: 1027 | B25: SwiftShip | C25: 46087 | D25: 46087 | E25: 46092 | F25: 46092 | G25: 46092 | H25: =LEN(B25)-LEN(TRIM(B25)) -> 0 | I25: =TRIM(B25) -> SwiftShip | J25: =VLOOKUP(A25,Orders!$A$2:$D$1201,4,FALSE) -> Delivered | K25: =IF(J25<>"Delivered","Not delivered",IF(OR(E25="",F25=""),"Unknown",IF(F25<=E25,"On time","Late"))) -> On time | L25: =IF(D25="","Not dispatched",IF(C25="","Unknown",IF(D25<=C25,"On time","Late"))) -> On time | O25: =IF(OR(F25="",G25=""),"",G25-F25) -> 0
A26: 1028 | B26: SwiftShip | C26: 46079 | D26: 46079 | E26: 46084 | F26: 46083 | G26: 46083 | H26: =LEN(B26)-LEN(TRIM(B26)) -> 0 | I26: =TRIM(B26) -> SwiftShip | J26: =VLOOKUP(A26,Orders!$A$2:$D$1201,4,FALSE) -> Delivered | K26: =IF(J26<>"Delivered","Not delivered",IF(OR(E26="",F26=""),"Unknown",IF(F26<=E26,"On time","Late"))) -> On time | L26: =IF(D26="","Not dispatched",IF(C26="","Unknown",IF(D26<=C26,"On time","Late"))) -> On time | O26: =IF(OR(F26="",G26=""),"",G26-F26) -> 0
A27: 1029 | B27: MetroLogistics | C27: 46150 | D27: 46150 | E27: 46155 | F27: 46155 | G27: 46155 | H27: =LEN(B27)-LEN(TRIM(B27)) -> 0 | I27: =TRIM(B27) -> MetroLogistics | J27: =VLOOKUP(A27,Orders!$A$2:$D$1201,4,FALSE) -> Delivered | K27: =IF(J27<>"Delivered","Not delivered",IF(OR(E27="",F27=""),"Unknown",IF(F27<=E27,"On time","Late"))) -> On time | L27: =IF(D27="","Not dispatched",IF(C27="","Unknown",IF(D27<=C27,"On time","Late"))) -> On time | O27: =IF(OR(F27="",G27=""),"",G27-F27) -> 0
A28: 1030 | B28: ParcelOne | C28: 46173 | D28: 46173 | E28: 46178 | F28: 46178 | G28: 46178 | H28: =LEN(B28)-LEN(TRIM(B28)) -> 0 | I28: =TRIM(B28) -> ParcelOne | J28: =VLOOKUP(A28,Orders!$A$2:$D$1201,4,FALSE) -> Delivered | K28: =IF(J28<>"Delivered","Not delivered",IF(OR(E28="",F28=""),"Unknown",IF(F28<=E28,"On time","Late"))) -> On time | L28: =IF(D28="","Not dispatched",IF(C28="","Unknown",IF(D28<=C28,"On time","Late"))) -> On time | O28: =IF(OR(F28="",G28=""),"",G28-F28) -> 0
A29: 1031 | B29: SwiftShip | C29: 46105 | D29: 46107 | E29: 46110 | F29: 46111 | G29: 46111 | H29: =LEN(B29)-LEN(TRIM(B29)) -> 0 | I29: =TRIM(B29) -> SwiftShip | J29: =VLOOKUP(A29,Orders!$A$2:$D$1201,4,FALSE) -> Delivered | K29: =IF(J29<>"Delivered","Not delivered",IF(OR(E29="",F29=""),"Unknown",IF(F29<=E29,"On time","Late"))) -> Late | L29: =IF(D29="","Not dispatched",IF(C29="","Unknown",IF(D29<=C29,"On time","Late"))) -> Late | O29: =IF(OR(F29="",G29=""),"",G29-F29) -> 0
A30: 1032 | B30: ParcelOne | C30: 46070 | D30: 46072 | E30: 46075 | F30: 46075 | G30: 46075 | H30: =LEN(B30)-LEN(TRIM(B30)) -> 0 | I30: =TRIM(B30) -> ParcelOne | J30: =VLOOKUP(A30,Orders!$A$2:$D$1201,4,FALSE) -> Delivered | K30: =IF(J30<>"Delivered","Not delivered",IF(OR(E30="",F30=""),"Unknown",IF(F30<=E30,"On time","Late"))) -> On time | L30: =IF(D30="","Not dispatched",IF(C30="","Unknown",IF(D30<=C30,"On time","Late"))) -> Late | O30: =IF(OR(F30="",G30=""),"",G30-F30) -> 0
A31: 1034 | B31: SwiftShip | C31: 46145 | D31: 46147 | E31: 46150 | F31: 46150 | G31: 46151 | H31: =LEN(B31)-LEN(TRIM(B31)) -> 0 | I31: =TRIM(B31) -> SwiftShip | J31: =VLOOKUP(A31,Orders!$A$2:$D$1201,4,FALSE) -> Delivered | K31: =IF(J31<>"Delivered","Not delivered",IF(OR(E31="",F31=""),"Unknown",IF(F31<=E31,"On time","Late"))) -> On time | L31: =IF(D31="","Not dispatched",IF(C31="","Unknown",IF(D31<=C31,"On time","Late"))) -> Late | O31: =IF(OR(F31="",G31=""),"",G31-F31) -> 1
A32: 1035 | B32: SwiftShip | C32: 46150 | D32: 46150 | E32: 46155 | F32: 46154 | G32: 46154 | H32: =LEN(B32)-LEN(TRIM(B32)) -> 0 | I32: =TRIM(B32) -> SwiftShip | J32: =VLOOKUP(A32,Orders!$A$2:$D$1201,4,FALSE) -> Delivered | K32: =IF(J32<>"Delivered","Not delivered",IF(OR(E32="",F32=""),"Unknown",IF(F32<=E32,"On time","Late"))) -> On time | L32: =IF(D32="","Not dispatched",IF(C32="","Unknown",IF(D32<=C32,"On time","Late"))) -> On time | O32: =IF(OR(F32="",G32=""),"",G32-F32) -> 0
A33: 1036 | B33: ParcelOne | C33: 46180 | D33: 46180 | E33: 46185 | F33: 46183 | G33: 46185 | H33: =LEN(B33)-LEN(TRIM(B33)) -> 0 | I33: =TRIM(B33) -> ParcelOne | J33: =VLOOKUP(A33,Orders!$A$2:$D$1201,4,FALSE) -> Delivered | K33: =IF(J33<>"Delivered","Not delivered",IF(OR(E33="",F33=""),"Unknown",IF(F33<=E33,"On time","Late"))) -> On time | L33: =IF(D33="","Not dispatched",IF(C33="","Unknown",IF(D33<=C33,"On time","Late"))) -> On time | O33: =IF(OR(F33="",G33=""),"",G33-F33) -> 2
A34: 1037 | B34: SwiftShip | C34: 46078 | D34: 46078 | E34: 46083 | F34: 46083 | G34: 46083 | H34: =LEN(B34)-LEN(TRIM(B34)) -> 0 | I34: =TRIM(B34) -> SwiftShip | J34: =VLOOKUP(A34,Orders!$A$2:$D$1201,4,FALSE) -> Delivered | K34: =IF(J34<>"Delivered","Not delivered",IF(OR(E34="",F34=""),"Unknown",IF(F34<=E34,"On time","Late"))) -> On time | L34: =IF(D34="","Not dispatched",IF(C34="","Unknown",IF(D34<=C34,"On time","Late"))) -> On time | O34: =IF(OR(F34="",G34=""),"",G34-F34) -> 0
... A45: 1049 | B45: SwiftShip | C45: 46097 | D45: 46097 | E45: 46102 | F45: 46102 | G45: 46102 | H45: =LEN(B45)-LEN(TRIM(B45)) -> 0 | I45: =TRIM(B45) -> SwiftShip | J45: =VLOOKUP(A45,Orders!$A$2:$D$1201,4,FALSE) -> Delivered | K45: =IF(J45<>"Delivered","Not delivered",IF(OR(E45="",F45=""),"Unknown",IF(F45<=E45,"On time","Late"))) -> On time | L45: =IF(D45="","Not dispatched",IF(C45="","Unknown",IF(D45<=C45,"On time","Late"))) -> On time | O45: =IF(OR(F45="",G45=""),"",G45-F45) -> 0
A46: 1050 | B46: MetroLogistics | C46: 46073 | E46: 46078 | H46: =LEN(B46)-LEN(TRIM(B46)) -> 0 | I46: =TRIM(B46) -> MetroLogistics | J46: =VLOOKUP(A46,Orders!$A$2:$D$1201,4,FALSE) -> Pending | K46: =IF(J46<>"Delivered","Not delivered",IF(OR(E46="",F46=""),"Unknown",IF(F46<=E46,"On time","Late"))) -> Not delivered | L46: =IF(D46="","Not dispatched",IF(C46="","Unknown",IF(D46<=C46,"On time","Late"))) -> Not dispatched | O46: =IF(OR(F46="",G46=""),"",G46-F46)
A47: 1051 | B47: SwiftShip | C47: 46122 | D47: 46123 | E47: 46127 | F47: 46127 | G47: 46127 | H47: =LEN(B47)-LEN(TRIM(B47)) -> 0 | I47: =TRIM(B47) -> SwiftShip | J47: =VLOOKUP(A47,Orders!$A$2:$D$1201,4,FALSE) -> Delivered | K47: =IF(J47<>"Delivered","Not delivered",IF(OR(E47="",F47=""),"Unknown",IF(F47<=E47,"On time","Late"))) -> On time | L47: =IF(D47="","Not dispatched",IF(C47="","Unknown",IF(D47<=C47,"On time","Late"))) -> Late | O47: =IF(OR(F47="",G47=""),"",G47-F47) -> 0
A48: 1052 | B48: MetroLogistics | C48: 46028 | D48: 46028 | E48: 46033 | F48: 46035 | G48: 46036 | H48: =LEN(B48)-LEN(TRIM(B48)) -> 0 | I48: =TRIM(B48) -> MetroLogistics | J48: =VLOOKUP(A48,Orders!$A$2:$D$1201,4,FALSE) -> Delivered | K48: =IF(J48<>"Delivered","Not delivered",IF(OR(E48="",F48=""),"Unknown",IF(F48<=E48,"On time","Late"))) -> Late | L48: =IF(D48="","Not dispatched",IF(C48="","Unknown",IF(D48<=C48,"On time","Late"))) -> On time | O48: =IF(OR(F48="",G48=""),"",G48-F48) -> 1
A49: 1053 | B49: SwiftShip | C49: 46122 | D49: 46122 | E49: 46127 | H49: =LEN(B49)-LEN(TRIM(B49)) -> 0 | I49: =TRIM(B49) -> SwiftShip | J49: =VLOOKUP(A49,Orders!$A$2:$D$1201,4,FALSE) -> Shipped | K49: =IF(J49<>"Delivered","Not delivered",IF(OR(E49="",F49=""),"Unknown",IF(F49<=E49,"On time","Late"))) -> Not delivered | L49: =IF(D49="","Not dispatched",IF(C49="","Unknown",IF(D49<=C49,"On time","Late"))) -> On time | O49: =IF(OR(F49="",G49=""),"",G49-F49)
A50: 1054 | B50: SwiftShip | C50: 46050 | D50: 46050 | E50: 46055 | F50: 46053 | G50: 46053 | H50: =LEN(B50)-LEN(TRIM(B50)) -> 0 | I50: =TRIM(B50) -> SwiftShip | J50: =VLOOKUP(A50,Orders!$A$2:$D$1201,4,FALSE) -> Delivered | K50: =IF(J50<>"Delivered","Not delivered",IF(OR(E50="",F50=""),"Unknown",IF(F50<=E50,"On time","Late"))) -> On time | L50: =IF(D50="","Not dispatched",IF(C50="","Unknown",IF(D50<=C50,"On time","Late"))) -> On time | O50: =IF(OR(F50="",G50=""),"",G50-F50) -> 0
...
